Workbook

Sheet 00_Readme
A1: Workbook Dummy Finance FMCG 2026
A2: Portfolio/interview workbook | PT Nusantara Consumer Brands | seluruh data bersifat dummy
A4: DISCLAIMER: Seluruh data, angka, nama proyek, risiko, status, dan asumsi di workbook ini dibuat untuk latihan portofolio/interview. Data tidak merepresentasikan perusahaan atau laporan keuangan nyata.
A7: Asumsi & Konvensi
A8: Assumption | B8: Value
A9: Company | B9: PT Nusantara Consumer Brands
A10: Industry | B10: FMCG / consumer goods
A11: Period | B11: Jan-Dec 2026
A12: Currency / unit | B12: IDR juta
A13: Scenario | B13: Actual, Annual Plan, Major Forecast, Rolling Forecast
A14: RAG warning threshold | B14: 0.05
A15: Input cell color | B15: Blue
A16: Formula / linked cell color | B16: Light green
A19: Legend
A20: Input / editable
A21: Formula / linked
A22: Green RAG
A23: Amber RAG
A24: Red RAG
A27: Pemetaan Tanggung Jawab Finance ke Sheet
A28: Tanggung jawab | B28: Contoh dummy data | C28: Sheet utama
A29: End-to-end P&L, BS, cash flow, audit & compliance | B29: P&L, balance sheet, cash flow, statutory/external/tax audit, controls | C29: 02_P&L; 03_Balance_Sheet; 04_Cash_Flow; 10_Audit_Compliance
A30: Annual Plan, Major Forecast, Rolling Forecast | B30: Scenario planning, variance, forecast accuracy | C30: 02_P&L; 05_Plan_Forecast; 01_Dashboard
A31: Drive consumption growth & commercial partnership | B31: Growth by region/channel/category, distribution, digital commerce, media | C31: 06_Growth_Drivers; 09_Business_Partnering
A32: Strategic projects and investment efficiency | B32: GTM, innovation, digital commerce, trade/A&P/media ROI | C32: 07_Strategic_Projects; 08_Investment_Efficiency
A33: Financial guidance, hygiene, and market risk | B33: Performance culture, commercial hygiene, risk register, RAG | C33: 09_Business_Partnering; 01_Dashboard

Sheet 01_Dashboard
A1: Finance FMCG Dashboard | 2026
A2: PT Nusantara Consumer Brands | formula-linked from detail sheets | IDR juta unless noted
A4: Revenue | D4: Gross Profit | G4: Gross Margin | J4: EBITDA | M4: EBITDA Margin
A5: ='02_P&L'!N6 | D5: ='02_P&L'!N8 | G5: ='02_P&L'!N9 | J5: ='02_P&L'!N13 | M5: ='02_P&L'!N14
A8: Ending Cash | D8: Net Working Capital | G8: Trade ROI | J8: Forecast Accuracy
A9: ='04_Cash_Flow'!M11 | D9: ='03_Balance_Sheet'!M21 | G9: =IFERROR(SUM('08_Investment_Efficiency'!K6:K113)/SUM('08_Investment_Efficiency'!D6:D113),0) | J9: =MAX(0,1-ABS(SUM('02_P&L'!B55:M55))/SUM('02_P&L'!B6:M6))
A13: Actual vs Annual Plan
A14: Month | B14: Actual Revenue | C14: Plan Revenue | D14: Actual EBITDA | E14: Plan EBITDA | F14: Revenue Var % | G14: EBITDA Var %
A15: Jan | B15: ='02_P&L'!B6 | C15: ='02_P&L'!B18 | D15: ='02_P&L'!B13 | E15: ='02_P&L'!B25 | F15: =IFERROR(B15/C15-1,0) | G15: =IFERROR(D15/E15-1,0)
A16: Feb | B16: ='02_P&L'!C6 | C16: ='02_P&L'!C18 | D16: ='02_P&L'!C13 | E16: ='02_P&L'!C25 | F16: =IFERROR(B16/C16-1,0) | G16: =IFERROR(D16/E16-1,0)
A17: Mar | B17: ='02_P&L'!D6 | C17: ='02_P&L'!D18 | D17: ='02_P&L'!D13 | E17: ='02_P&L'!D25 | F17: =IFERROR(B17/C17-1,0) | G17: =IFERROR(D17/E17-1,0)
A18: Apr | B18: ='02_P&L'!E6 | C18: ='02_P&L'!E18 | D18: ='02_P&L'!E13 | E18: ='02_P&L'!E25 | F18: =IFERROR(B18/C18-1,0) | G18: =IFERROR(D18/E18-1,0)
A19: May | B19: ='02_P&L'!F6 | C19: ='02_P&L'!F18 | D19: ='02_P&L'!F13 | E19: ='02_P&L'!F25 | F19: =IFERROR(B19/C19-1,0) | G19: =IFERROR(D19/E19-1,0)
A20: Jun | B20: ='02_P&L'!G6 | C20: ='02_P&L'!G18 | D20: ='02_P&L'!G13 | E20: ='02_P&L'!G25 | F20: =IFERROR(B20/C20-1,0) | G20: =IFERROR(D20/E20-1,0)
A21: Jul | B21: ='02_P&L'!H6 | C21: ='02_P&L'!H18 | D21: ='02_P&L'!H13 | E21: ='02_P&L'!H25 | F21: =IFERROR(B21/C21-1,0) | G21: =IFERROR(D21/E21-1,0)
A22: Aug | B22: ='02_P&L'!I6 | C22: ='02_P&L'!I18 | D22: ='02_P&L'!I13 | E22: ='02_P&L'!I25 | F22: =IFERROR(B22/C22-1,0) | G22: =IFERROR(D22/E22-1,0)
A23: Sep | B23: ='02_P&L'!J6 | C23: ='02_P&L'!J18 | D23: ='02_P&L'!J13 | E23: ='02_P&L'!J25 | F23: =IFERROR(B23/C23-1,0) | G23: =IFERROR(D23/E23-1,0)
A24: Oct | B24: ='02_P&L'!K6 | C24: ='02_P&L'!K18 | D24: ='02_P&L'!K13 | E24: ='02_P&L'!K25 | F24: =IFERROR(B24/C24-1,0) | G24: =IFERROR(D24/E24-1,0)
A25: Nov | B25: ='02_P&L'!L6 | C25: ='02_P&L'!L18 | D25: ='02_P&L'!L13 | E25: ='02_P&L'!L25 | F25: =IFERROR(B25/C25-1,0) | G25: =IFERROR(D25/E25-1,0)
A26: Dec | B26: ='02_P&L'!M6 | C26: ='02_P&L'!M18 | D26: ='02_P&L'!M13 | E26: ='02_P&L'!M25 | F26: =IFERROR(B26/C26-1,0) | G26: =IFERROR(D26/E26-1,0)
A30: Largest Variances
A31: Metric | B31: Month | C31: Variance | D31: Interpretation
A32: Revenue | B32: =INDEX($A$15:$A$26,MATCH(MIN($F$15:$F$26),$F$15:$F$26,0)) | C32: =MIN($F$15:$F$26) | D32: =IF(C32<0,"Below plan","Above plan")
A33: EBITDA | B33: =INDEX($A$15:$A$26,MATCH(MIN($G$15:$G$26),$G$15:$G$26,0)) | C33: =MIN($G$15:$G$26) | D33: =IF(C33<0,"Below plan","Above plan")
A36: Strategic Project Status
A37: RAG | B37: Count | C37: Meaning
A38: Green | B38: =COUNTIF('07_Strategic_Projects'!$O$6:$O$13,A38) | C38: On track / completed
A39: Amber | B39: =COUNTIF('07_Strategic_Projects'!$O$6:$O$13,A39) | C39: At risk
A40: Red | B40: =COUNTIF('07_Strategic_Projects'!$O$6:$O$13,A40) | C40: Delayed
A44: Market Risk RAG
A45: RAG | B45: Count | C45: Action
A46: Green | B46: =COUNTIF('09_Business_Partnering'!$K$20:$K$27,A46) | C46: Monitor
A47: Amber | B47: =COUNTIF('09_Business_Partnering'!$K$20:$K$27,A47) | C47: Mitigate
A48: Red | B48: =COUNTIF('09_Business_Partnering'!$K$20:$K$27,A48) | C48: Escalate

Sheet 02_P&L
A1: P&L | Actual vs Plan & Forecast
A2: IDR juta | blue cells are editable inputs; light green cells are formulas or links
A4: Metric | B4: Jan 2026 | C4: Feb 2026 | D4: Mar 2026 | E4: Apr 2026 | F4: May 2026 | G4: Jun 2026 | H4: Jul 2026 | I4: Aug 2026 | J4: Sep 2026 | K4: Oct 2026 | L4: Nov 2026 | M4: Dec 2026 | N4: FY 2026
A5: Actual
A6: Revenue | B6: 12500 | C6: 13210 | D6: 12900 | E6: 13620 | F6: 14040 | G6: 14550 | H6: 14250 | I6: 14980 | J6: 15480 | K6: 16010 | L6: 16680 | M6: 17580 | N6: =SUM(B6:M6)
A7: COGS | B7: 6813 | C7: 7279 | D7: 7185 | E7: 7668 | F7: 7652 | G7: 8017 | H7: 7937 | I7: 8434 | J7: 8437 | K7: 8822 | L7: 9291 | M7: 9898 | N7: =SUM(B7:M7)
A8: Gross Profit | B8: =B6-B7 | C8: =C6-C7 | D8: =D6-D7 | E8: =E6-E7 | F8: =F6-F7 | G8: =G6-G7 | H8: =H6-H7 | I8: =I6-I7 | ... M8: =M6-M7 | N8: =SUM(B8:M8)
A9: Gross Margin | B9: =IFERROR(B8/B6,0) | C9: =IFERROR(C8/C6,0) | D9: =IFERROR(D8/D6,0) | E9: =IFERROR(E8/E6,0) | F9: =IFERROR(F8/F6,0) | G9: =IFERROR(G8/G6,0) | H9: =IFERROR(H8/H6,0) | I9: =IFERROR(I8/I6,0) | ... N9: =IFERROR(N8/N6,0)
A10: Trade Investment | B10: 938 | C10: 1044 | D10: 1071 | E10: 1022 | F10: 1109 | G10: 1208 | H10: 1069 | I10: 1183 | J10: 1285 | K10: 1201 | L10: 1318 | M10: 1459 | N10: =SUM(B10:M10)
A11: A&P | B11: 425 | C11: 476 | D11: 490 | E11: 545 | F11: 477 | G11: 524 | H11: 542 | I11: 599 | J11: 526 | K11: 576 | L11: 634 | M11: 703 | N11: =SUM(B11:M11)
A12: Overhead | B12: 1450 | C12: 1507 | D12: 1564 | E12: 1516 | F12: 1573 | G12: 1630 | H12: 1582 | I12: 1639 | J12: 1696 | K12: 1648 | L12: 1705 | M12: 1762 | N12: =SUM(B12:M12)
A13: EBITDA | B13: =B8-B10-B11-B12 | C13: =C8-C10-C11-C12 | D13: =D8-D10-D11-D12 | E13: =E8-E10-E11-E12 | F13: =F8-F10-F11-F12 | G13: =G8-G10-G11-G12 | H13: =H8-H10-H11-H12 | I13: =I8-I10-I11-I12 | ... M13: =M8-M10-M11-M12 | N13: =SUM(B13:M13)
A14: EBITDA Margin | B14: =IFERROR(B13/B6,0) | C14: =IFERROR(C13/C6,0) | D14: =IFERROR(D13/D6,0) | E14: =IFERROR(E13/E6,0) | F14: =IFERROR(F13/F6,0) | G14: =IFERROR(G13/G6,0) | H14: =IFERROR(H13/H6,0) | I14: =IFERROR(I13/I6,0) | ... N14: =IFERROR(N13/N6,0)
A17: Annual Plan
A18: Revenue | B18: 12937 | C18: 13752 | D18: 13506 | E18: 14097 | F18: 14616 | G18: 15234 | H18: 14749 | I18: 15594 | J18: 16208 | K18: 16570 | L18: 17364 | M18: 18406 | N18: =SUM(B18:M18)
A19: COGS | B19: 6986 | C19: 7481 | D19: 7401 | E19: 7782 | F19: 7893 | G19: 8287 | H19: 8082 | I19: 8608 | J19: 8752 | K19: 9014 | L19: 9515 | M19: 10160 | N19: =SUM(B19:M19)
A20: Gross Profit | B20: =B18-B19 | C20: =C18-C19 | D20: =D18-D19 | E20: =E18-E19 | F20: =F18-F19 | G20: =G18-G19 | H20: =H18-H19 | I20: =I18-I19 | ... M20: =M18-M19 | N20: =SUM(B20:M20)
A21: Gross Margin | B21: =IFERROR(B20/B18,0) | C21: =IFERROR(C20/C18,0) | D21: =IFERROR(D20/D18,0) | E21: =IFERROR(E20/E18,0) | F21: =IFERROR(F20/F18,0) | G21: =IFERROR(G20/G18,0) | H21: =IFERROR(H20/H18,0) | I21: =IFERROR(I20/I18,0) | ... N21: =IFERROR(N20/N18,0)
A22: Trade Investment | B22: 944 | C22: 1045 | D22: 986 | E22: 1071 | F22: 1067 | G22: 1158 | H22: 1077 | I22: 1185 | J22: 1183 | K22: 1259 | L22: 1268 | M22: 1399 | N22: =SUM(B22:M22)
A23: A&P | B23: 414 | C23: 454 | D23: 459 | E23: 451 | F23: 482 | G23: 518 | H23: 472 | I23: 515 | J23: 551 | K23: 530 | L23: 573 | M23: 626 | N23: =SUM(B23:M23)
A24: Overhead | B24: 1420 | C24: 1440 | D24: 1460 | E24: 1480 | F24: 1500 | G24: 1520 | H24: 1540 | I24: 1560 | J24: 1580 | K24: 1600 | L24: 1620 | M24: 1640 | N24: =SUM(B24:M24)
A25: EBITDA | B25: =B20-B22-B23-B24 | C25: =C20-C22-C23-C24 | D25: =D20-D22-D23-D24 | E25: =E20-E22-E23-E24 | F25: =F20-F22-F23-F24 | G25: =G20-G22-G23-G24 | H25: =H20-H22-H23-H24 | I25: =I20-I22-I23-I24 | ... M25: =M20-M22-M23-M24 | N25: =SUM(B25:M25)
A26: EBITDA Margin | B26: =IFERROR(B25/B18,0) | C26: =IFERROR(C25/C18,0) | D26: =IFERROR(D25/D18,0) | E26: =IFERROR(E25/E18,0) | F26: =IFERROR(F25/F18,0) | G26: =IFERROR(G25/G18,0) | H26: =IFERROR(H25/H18,0) | I26: =IFERROR(I25/I18,0) | ... N26: =IFERROR(N25/N18,0)
A29: Major Forecast
A30: Revenue | B30: 12650 | C30: 13421 | D30: 13158 | E30: 13947 | F30: 14208 | G30: 14783 | H30: 14535 | I30: 15340 | J30: 15666 | K30: 16266 | L30: 17014 | M30: 18002 | N30: =SUM(B30:M30)
A31: COGS | B31: 6856 | C31: 7328 | D31: 7237 | E31: 7727 | F31: 7928 | G31: 8012 | H31: 7936 | I31: 8437 | J31: 8679 | K31: 9076 | L31: 9222 | M31: 9829 | N31: =SUM(B31:M31)
A32: Gross Profit | B32: =B30-B31 | C32: =C30-C31 | D32: =D30-D31 | E32: =E30-E31 | F32: =F30-F31 | G32: =G30-G31 | H32: =H30-H31 | I32: =I30-I31 | ... M32: =M30-M31 | N32: =SUM(B32:M32)
A33: Gross Margin | B33: =IFERROR(B32/B30,0) | C33: =IFERROR(C32/C30,0) | D33: =IFERROR(D32/D30,0) | E33: =IFERROR(E32/E30,0) | F33: =IFERROR(F32/F30,0) | G33: =IFERROR(G32/G30,0) | H33: =IFERROR(H32/H30,0) | I33: =IFERROR(I32/I30,0) | ... N33: =IFERROR(N32/N30,0)
A34: Trade Investment | B34: 961 | C34: 1047 | D34: 1053 | E34: 1060 | F34: 1108 | G34: 1183 | H34: 1105 | I34: 1197 | J34: 1253 | K34: 1236 | L34: 1327 | M34: 1440 | N34: =SUM(B34:M34)
A35: A&P | B35: 443 | C35: 483 | D35: 487 | E35: 530 | F35: 497 | G35: 532 | H35: 538 | I35: 583 | J35: 548 | K35: 586 | L35: 630 | M35: 684 | N35: =SUM(B35:M35)
A36: Overhead | B36: 1460 | C36: 1482 | D36: 1504 | E36: 1526 | F36: 1548 | G36: 1570 | H36: 1592 | I36: 1614 | J36: 1636 | K36: 1658 | L36: 1680 | M36: 1702 | N36: =SUM(B36:M36)
A37: EBITDA | B37: =B32-B34-B35-B36 | C37: =C32-C34-C35-C36 | D37: =D32-D34-D35-D36 | E37: =E32-E34-E35-E36 | F37: =F32-F34-F35-F36 | G37: =G32-G34-G35-G36 | H37: =H32-H34-H35-H36 | I37: =I32-I34-I35-I36 | ... M37: =M32-M34-M35-M36 | N37: =SUM(B37:M37)
A38: EBITDA Margin | B38: =IFERROR(B37/B30,0) | C38: =IFERROR(C37/C30,0) | D38: =IFERROR(D37/D30,0) | E38: =IFERROR(E37/E30,0) | F38: =IFERROR(F37/F30,0) | G38: =IFERROR(G37/G30,0) | H38: =IFERROR(H37/H30,0) | I38: =IFERROR(I37/I30,0) | ... N38: =IFERROR(N37/N30,0)
A41: Rolling Forecast
A42: Revenue | B42: 12750 | C42: 13514 | D42: 13235 | E42: 14015 | F42: 14489 | G42: 14841 | H42: 14578 | I42: 15369 | J42: 15929 | K42: 16522 | L42: 17014 | M42: 17984 | N42: =SUM(B42:M42)
A43: COGS | B43: 6898 | C43: 7379 | D43: 7292 | E43: 7792 | F43: 7839 | G43: 8103 | H43: 8032 | I43: 8545 | J43: 8618 | K43: 9021 | L43: 9375 | M43: 9999 | N43: =SUM(B43:M43)
A44: Gross Profit | B44: =B42-B43 | C44: =C42-C43 | D44: =D42-D43 | E44: =E42-E43 | F44: =F42-F43 | G44: =G42-G43 | H44: =H42-H43 | I44: =I42-I43 | ... M44: =M42-M43 | N44: =SUM(B44:M44)
A45: Gross Margin | B45: =IFERROR(B44/B42,0) | C45: =IFERROR(C44/C42,0) | D45: =IFERROR(D44/D42,0) | E45: =IFERROR(E44/E42,0) | F45: =IFERROR(F44/F42,0) | G45: =IFERROR(G44/G42,0) | H45: =IFERROR(H44/H42,0) | I45: =IFERROR(I44/I42,0) | ... N45: =IFERROR(N44/N42,0)
A46: Trade Investment | B46: 944 | C46: 1041 | D46: 1059 | E46: 1037 | F46: 1116 | G46: 1187 | H46: 1079 | I46: 1183 | J46: 1274 | K46: 1223 | L46: 1310 | M46: 1439 | N46: =SUM(B46:M46)
A47: A&P | B47: 421 | C47: 459 | D47: 463 | E47: 505 | F47: 478 | G47: 505 | H47: 510 | I47: 553 | J47: 526 | K47: 562 | L47: 595 | M47: 647 | N47: =SUM(B47:M47)
...

Sheet 03_Balance_Sheet
A1: Balance Sheet | Working Capital & Liquidity
A2: IDR juta | cash is linked to Cash Flow; equity plugs to maintain balance in dummy data
A4: Metric | B4: Jan 2026 | C4: Feb 2026 | D4: Mar 2026 | E4: Apr 2026 | F4: May 2026 | G4: Jun 2026 | H4: Jul 2026 | I4: Aug 2026 | J4: Sep 2026 | K4: Oct 2026 | L4: Nov 2026 | M4: Dec 2026 | N4: FY 2026
A5: Assets
A6: Cash | B6: ='04_Cash_Flow'!B11 | C6: ='04_Cash_Flow'!C11 | D6: ='04_Cash_Flow'!D11 | E6: ='04_Cash_Flow'!E11 | F6: ='04_Cash_Flow'!F11 | G6: ='04_Cash_Flow'!G11 | H6: ='04_Cash_Flow'!H11 | I6: ='04_Cash_Flow'!I11 | ... M6: ='04_Cash_Flow'!M11 | N6: =M6
A7: Account Receivable | B7: ='02_P&L'!B6*0.34 | C7: ='02_P&L'!C6*0.35000000000000003 | D7: ='02_P&L'!D6*0.36000000000000004 | E7: ='02_P&L'!E6*0.34 | F7: ='02_P&L'!F6*0.35000000000000003 | G7: ='02_P&L'!G6*0.36000000000000004 | H7: ='02_P&L'!H6*0.34 | I7: ='02_P&L'!I6*0.35000000000000003 | J7: ='02_P&L'!J6*0.36000000000000004 | K7: ='02_P&L'!K6*0.34 | L7: ='02_P&L'!L6*0.35000000000000003 | M7: ='02_P&L'!M6*0.36000000000000004 | N7: =M7
A8: Inventory | B8: ='02_P&L'!B7*0.13 | C8: ='02_P&L'!C7*0.136 | D8: ='02_P&L'!D7*0.14200000000000002 | E8: ='02_P&L'!E7*0.14800000000000002 | F8: ='02_P&L'!F7*0.13 | G8: ='02_P&L'!G7*0.136 | H8: ='02_P&L'!H7*0.14200000000000002 | I8: ='02_P&L'!I7*0.14800000000000002 | J8: ='02_P&L'!J7*0.13 | K8: ='02_P&L'!K7*0.136 | L8: ='02_P&L'!L7*0.14200000000000002 | M8: ='02_P&L'!M7*0.14800000000000002 | N8: =M8
A9: Other Current Assets | B9: ='02_P&L'!B6*0.045 | C9: ='02_P&L'!C6*0.045 | D9: ='02_P&L'!D6*0.045 | E9: ='02_P&L'!E6*0.045 | F9: ='02_P&L'!F6*0.045 | G9: ='02_P&L'!G6*0.045 | H9: ='02_P&L'!H6*0.045 | I9: ='02_P&L'!I6*0.045 | ... M9: ='02_P&L'!M6*0.045 | N9: =M9
A10: Total Current Assets | B10: =SUM(B6:B9) | C10: =SUM(C6:C9) | D10: =SUM(D6:D9) | E10: =SUM(E6:E9) | F10: =SUM(F6:F9) | G10: =SUM(G6:G9) | H10: =SUM(H6:H9) | I10: =SUM(I6:I9) | ... M10: =SUM(M6:M9) | N10: =M10
A11: Fixed Assets | B11: 11000 | C11: 11255 | D11: 11510 | E11: 11525 | F11: 11780 | G11: 12035 | H11: 12050 | I11: 12305 | J11: 12560 | K11: 12575 | L11: 12830 | M11: 13085 | N11: =M11
A12: Total Assets | B12: =B10+B11 | C12: =C10+C11 | D12: =D10+D11 | E12: =E10+E11 | F12: =F10+F11 | G12: =G10+G11 | H12: =H10+H11 | I12: =I10+I11 | ... M12: =M10+M11 | N12: =M12
A14: Liabilities & Equity
A15: Debt | B15: ='02_P&L'!B7*0.135 | C15: ='02_P&L'!C7*0.14 | D15: ='02_P&L'!D7*0.14500000000000002 | E15: ='02_P&L'!E7*0.135 | F15: ='02_P&L'!F7*0.14 | G15: ='02_P&L'!G7*0.14500000000000002 | H15: ='02_P&L'!H7*0.135 | I15: ='02_P&L'!I7*0.14 | J15: ='02_P&L'!J7*0.14500000000000002 | K15: ='02_P&L'!K7*0.135 | L15: ='02_P&L'!L7*0.14 | M15: ='02_P&L'!M7*0.14500000000000002 | N15: =M15
A16: Total Liabilities | B16: 8200 | C16: 8450 | D16: 8700 | E16: 8950 | F16: 8200 | G16: 8450 | H16: 8700 | I16: 8950 | J16: 8200 | K16: 8450 | L16: 8700 | M16: 8950 | N16: =M16
A17: Equity | B17: =SUM(B15:B16) | C17: =SUM(C15:C16) | D17: =SUM(D15:D16) | E17: =SUM(E15:E16) | F17: =SUM(F15:F16) | G17: =SUM(G15:G16) | H17: =SUM(H15:H16) | I17: =SUM(I15:I16) | ... M17: =SUM(M15:M16) | N17: =M17
A18: Total Liabilities & Equity | B18: =B12-B17 | C18: =C12-C17 | D18: =D12-D17 | E18: =E12-E17 | F18: =F12-F17 | G18: =G12-G17 | H18: =H12-H17 | I18: =I12-I17 | ... M18: =M12-M17 | N18: =M18
B19: =SUM(B17:B18) | C19: =SUM(C17:C18) | D19: =SUM(D17:D18) | E19: =SUM(E17:E18) | F19: =SUM(F17:F18) | G19: =SUM(G17:G18) | H19: =SUM(H17:H18) | I19: =SUM(I17:I18) | ... M19: =SUM(M17:M18) | N19: =M19
A20: Net Working Capital
A21: DSO (days) | B21: =B7+B8-B15 | C21: =C7+C8-C15 | D21: =D7+D8-D15 | E21: =E7+E8-E15 | F21: =F7+F8-F15 | G21: =G7+G8-G15 | H21: =H7+H8-H15 | I21: =I7+I8-I15 | ... M21: =M7+M8-M15 | N21: =M21
A22: DIO (days) | B22: =IFERROR(B7/'02_P&L'!B6*365,0) | C22: =IFERROR(C7/'02_P&L'!C6*365,0) | D22: =IFERROR(D7/'02_P&L'!D6*365,0) | E22: =IFERROR(E7/'02_P&L'!E6*365,0) | F22: =IFERROR(F7/'02_P&L'!F6*365,0) | G22: =IFERROR(G7/'02_P&L'!G6*365,0) | H22: =IFERROR(H7/'02_P&L'!H6*365,0) | I22: =IFERROR(I7/'02_P&L'!I6*365,0) | ... N22: =IFERROR(N7/'02_P&L'!N6*365,0)
A23: DPO (days) | B23: =IFERROR(B8/'02_P&L'!B7*365,0) | C23: =IFERROR(C8/'02_P&L'!C7*365,0) | D23: =IFERROR(D8/'02_P&L'!D7*365,0) | E23: =IFERROR(E8/'02_P&L'!E7*365,0) | F23: =IFERROR(F8/'02_P&L'!F7*365,0) | G23: =IFERROR(G8/'02_P&L'!G7*365,0) | H23: =IFERROR(H8/'02_P&L'!H7*365,0) | I23: =IFERROR(I8/'02_P&L'!I7*365,0) | ... N23: =IFERROR(N8/'02_P&L'!N7*365,0)
B24: =IFERROR(B15/'02_P&L'!B7*365,0) | C24: =IFERROR(C15/'02_P&L'!C7*365,0) | D24: =IFERROR(D15/'02_P&L'!D7*365,0) | E24: =IFERROR(E15/'02_P&L'!E7*365,0) | F24: =IFERROR(F15/'02_P&L'!F7*365,0) | G24: =IFERROR(G15/'02_P&L'!G7*365,0) | H24: =IFERROR(H15/'02_P&L'!H7*365,0) | I24: =IFERROR(I15/'02_P&L'!I7*365,0) | ... N24: =IFERROR(N15/'02_P&L'!N7*365,0)
A25: Working Capital Metrics

Sheet 04_Cash_Flow
A1: Cash Flow | Actual Cash Bridge
A2: IDR juta | ending cash is formula-driven and feeds Balance Sheet and Dashboard
A4: Metric | B4: Jan 2026 | C4: Feb 2026 | D4: Mar 2026 | E4: Apr 2026 | F4: May 2026 | G4: Jun 2026 | H4: Jul 2026 | I4: Aug 2026 | J4: Sep 2026 | K4: Oct 2026 | L4: Nov 2026 | M4: Dec 2026 | N4: FY 2026
A5: Cash Flow
A6: Beginning Cash | B6: 9000 | C6: =B11 | D6: =C11 | E6: =D11 | F6: =E11 | G6: =F11 | H6: =G11 | I6: =H11 | J6: =I11 | ... M6: =L11 | N6: =B6
A7: Cash Flow from Operations | B7: 2250 | C7: 2510 | D7: 2580 | E7: 2452 | F7: 2668 | G7: 2910 | H7: 2565 | I7: 2846 | J7: 3096 | K7: 2882 | L7: 3169 | M7: 3516 | N7: =SUM(B7:M7)
A8: Cash Flow from Investing | B8: -420 | C8: -473 | D8: -526 | E8: -579 | F8: -492 | G8: -545 | H8: -598 | I8: -651 | J8: -564 | K8: -617 | L8: -670 | M8: -723 | N8: =SUM(B8:M8)
A9: Cash Flow from Financing | B9: 0 | C9: 0 | D9: -250 | E9: 0 | F9: 0 | G9: -300 | H9: 0 | I9: 0 | J9: -450 | K9: 0 | L9: 0 | M9: -600 | N9: =SUM(B9:M9)
A10: Net Cash Change | B10: =SUM(B7:B9) | C10: =SUM(C7:C9) | D10: =SUM(D7:D9) | E10: =SUM(E7:E9) | F10: =SUM(F7:F9) | G10: =SUM(G7:G9) | H10: =SUM(H7:H9) | I10: =SUM(I7:I9) | ... M10: =SUM(M7:M9) | N10: =SUM(B10:M10)
A11: Ending Cash | B11: =B6+B10 | C11: =C6+C10 | D11: =D6+D10 | E11: =E6+E10 | F11: =F6+F10 | G11: =G6+G10 | H11: =H6+H10 | I11: =I6+I10 | ... M11: =M6+M10 | N11: =M11
A12: Plan Ending Cash | B12: 11047 | C12: 13202 | D12: 15140 | E12: 16875 | F12: 19207 | G12: 21450 | H12: 23207 | I12: 25596 | J12: 27894 | K12: 29880 | L12: 32620 | M12: 35074 | N12: =M12
A13: Variance vs Plan | B13: =B11-B12 | C13: =C11-C12 | D13: =D11-D12 | E13: =E11-E12 | F13: =F11-F12 | G13: =G11-G12 | H13: =H11-H12 | I13: =I11-I12 | ... M13: =M11-M12 | N13: =M13

Sheet 05_Plan_Forecast
A1: Plan & Forecast
A2: Formula-linked scenario summary | IDR juta | edit source scenarios in 02_P&L
A4: Metric | B4: Jan 2026 | C4: Feb 2026 | D4: Mar 2026 | E4: Apr 2026 | F4: May 2026 | G4: Jun 2026 | H4: Jul 2026 | I4: Aug 2026 | J4: Sep 2026 | K4: Oct 2026 | L4: Nov 2026 | M4: Dec 2026 | N4: FY 2026
A5: Annual Plan
A6: Revenue | B6: ='02_P&L'!B18 | C6: ='02_P&L'!C18 | D6: ='02_P&L'!D18 | E6: ='02_P&L'!E18 | F6: ='02_P&L'!F18 | G6: ='02_P&L'!G18 | H6: ='02_P&L'!H18 | I6: ='02_P&L'!I18 | ... N6: ='02_P&L'!N18
A7: Gross Margin | B7: ='02_P&L'!B21 | C7: ='02_P&L'!C21 | D7: ='02_P&L'!D21 | E7: ='02_P&L'!E21 | F7: ='02_P&L'!F21 | G7: ='02_P&L'!G21 | H7: ='02_P&L'!H21 | I7: ='02_P&L'!I21 | ... N7: ='02_P&L'!N21
A8: EBITDA | B8: ='02_P&L'!B25 | C8: ='02_P&L'!C25 | D8: ='02_P&L'!D25 | E8: ='02_P&L'!E25 | F8: ='02_P&L'!F25 | G8: ='02_P&L'!G25 | H8: ='02_P&L'!H25 | I8: ='02_P&L'!I25 | ... N8: ='02_P&L'!N25
A9: Cash | B9: ='04_Cash_Flow'!B12 | C9: ='04_Cash_Flow'!C12 | D9: ='04_Cash_Flow'!D12 | E9: ='04_Cash_Flow'!E12 | F9: ='04_Cash_Flow'!F12 | G9: ='04_Cash_Flow'!G12 | H9: ='04_Cash_Flow'!H12 | I9: ='04_Cash_Flow'!I12 | ... M9: ='04_Cash_Flow'!M12 | N9: =M9
A10: Trade Investment | B10: ='02_P&L'!B22 | C10: ='02_P&L'!C22 | D10: ='02_P&L'!D22 | E10: ='02_P&L'!E22 | F10: ='02_P&L'!F22 | G10: ='02_P&L'!G22 | H10: ='02_P&L'!H22 | I10: ='02_P&L'!I22 | ... M10: ='02_P&L'!M22 | N10: ='02_P&L'!N25
A11: A&P | B11: ='02_P&L'!B23 | C11: ='02_P&L'!C23 | D11: ='02_P&L'!D23 | E11: ='02_P&L'!E23 | F11: ='02_P&L'!F23 | G11: ='02_P&L'!G23 | H11: ='02_P&L'!H23 | I11: ='02_P&L'!I23 | ... M11: ='02_P&L'!M23 | N11: ='02_P&L'!N26
A12: Overhead Target | B12: ='02_P&L'!B24 | C12: ='02_P&L'!C24 | D12: ='02_P&L'!D24 | E12: ='02_P&L'!E24 | F12: ='02_P&L'!F24 | G12: ='02_P&L'!G24 | H12: ='02_P&L'!H24 | I12: ='02_P&L'!I24 | ... M12: ='02_P&L'!M24 | N12: ='02_P&L'!N27
A15: Major Forecast
A16: Revenue | B16: ='02_P&L'!B30 | C16: ='02_P&L'!C30 | D16: ='02_P&L'!D30 | E16: ='02_P&L'!E30 | F16: ='02_P&L'!F30 | G16: ='02_P&L'!G30 | H16: ='02_P&L'!H30 | I16: ='02_P&L'!I30 | ... N16: ='02_P&L'!N30
A17: Gross Margin | B17: ='02_P&L'!B33 | C17: ='02_P&L'!C33 | D17: ='02_P&L'!D33 | E17: ='02_P&L'!E33 | F17: ='02_P&L'!F33 | G17: ='02_P&L'!G33 | H17: ='02_P&L'!H33 | I17: ='02_P&L'!I33 | ... N17: ='02_P&L'!N33
A18: EBITDA | B18: ='02_P&L'!B37 | C18: ='02_P&L'!C37 | D18: ='02_P&L'!D37 | E18: ='02_P&L'!E37 | F18: ='02_P&L'!F37 | G18: ='02_P&L'!G37 | H18: ='02_P&L'!H37 | I18: ='02_P&L'!I37 | ... N18: ='02_P&L'!N37
A19: Cash | B19: ='04_Cash_Flow'!B11 | C19: ='04_Cash_Flow'!C11 | D19: ='04_Cash_Flow'!D11 | E19: ='04_Cash_Flow'!E11 | F19: ='04_Cash_Flow'!F11 | G19: ='04_Cash_Flow'!G11 | H19: ='04_Cash_Flow'!H11 | I19: ='04_Cash_Flow'!I11 | ... M19: ='04_Cash_Flow'!M11 | N19: =M19
A20: Trade Investment | B20: ='02_P&L'!B34 | C20: ='02_P&L'!C34 | D20: ='02_P&L'!D34 | E20: ='02_P&L'!E34 | F20: ='02_P&L'!F34 | G20: ='02_P&L'!G34 | H20: ='02_P&L'!H34 | I20: ='02_P&L'!I34 | ... M20: ='02_P&L'!M34 | N20: ='02_P&L'!N37
A21: A&P | B21: ='02_P&L'!B35 | C21: ='02_P&L'!C35 | D21: ='02_P&L'!D35 | E21: ='02_P&L'!E35 | F21: ='02_P&L'!F35 | G21: ='02_P&L'!G35 | H21: ='02_P&L'!H35 | I21: ='02_P&L'!I35 | ... M21: ='02_P&L'!M35 | N21: ='02_P&L'!N38
A22: Overhead Target | B22: ='02_P&L'!B36 | C22: ='02_P&L'!C36 | D22: ='02_P&L'!D36 | E22: ='02_P&L'!E36 | F22: ='02_P&L'!F36 | G22: ='02_P&L'!G36 | H22: ='02_P&L'!H36 | I22: ='02_P&L'!I36 | ... M22: ='02_P&L'!M36 | N22: ='02_P&L'!N39
A25: Rolling Forecast
A26: Revenue | B26: ='02_P&L'!B42 | C26: ='02_P&L'!C42 | D26: ='02_P&L'!D42 | E26: ='02_P&L'!E42 | F26: ='02_P&L'!F42 | G26: ='02_P&L'!G42 | H26: ='02_P&L'!H42 | I26: ='02_P&L'!I42 | ... N26: ='02_P&L'!N42
A27: Gross Margin | B27: ='02_P&L'!B45 | C27: ='02_P&L'!C45 | D27: ='02_P&L'!D45 | E27: ='02_P&L'!E45 | F27: ='02_P&L'!F45 | G27: ='02_P&L'!G45 | H27: ='02_P&L'!H45 | I27: ='02_P&L'!I45 | ... N27: ='02_P&L'!N45
A28: EBITDA | B28: ='02_P&L'!B49 | C28: ='02_P&L'!C49 | D28: ='02_P&L'!D49 | E28: ='02_P&L'!E49 | F28: ='02_P&L'!F49 | G28: ='02_P&L'!G49 | H28: ='02_P&L'!H49 | I28: ='02_P&L'!I49 | ... N28: ='02_P&L'!N49
A29: Cash | B29: ='04_Cash_Flow'!B11 | C29: ='04_Cash_Flow'!C11 | D29: ='04_Cash_Flow'!D11 | E29: ='04_Cash_Flow'!E11 | F29: ='04_Cash_Flow'!F11 | G29: ='04_Cash_Flow'!G11 | H29: ='04_Cash_Flow'!H11 | I29: ='04_Cash_Flow'!I11 | ... M29: ='04_Cash_Flow'!M11 | N29: =M29
A30: Trade Investment | B30: ='02_P&L'!B46 | C30: ='02_P&L'!C46 | D30: ='02_P&L'!D46 | E30: ='02_P&L'!E46 | F30: ='02_P&L'!F46 | G30: ='02_P&L'!G46 | H30: ='02_P&L'!H46 | I30: ='02_P&L'!I46 | ... M30: ='02_P&L'!M46 | N30: ='02_P&L'!N49
A31: A&P | B31: ='02_P&L'!B47 | C31: ='02_P&L'!C47 | D31: ='02_P&L'!D47 | E31: ='02_P&L'!E47 | F31: ='02_P&L'!F47 | G31: ='02_P&L'!G47 | H31: ='02_P&L'!H47 | I31: ='02_P&L'!I47 | ... M31: ='02_P&L'!M47 | N31: ='02_P&L'!N50
A32: Overhead Target | B32: ='02_P&L'!B48 | C32: ='02_P&L'!C48 | D32: ='02_P&L'!D48 | E32: ='02_P&L'!E48 | F32: ='02_P&L'!F48 | G32: ='02_P&L'!G48 | H32: ='02_P&L'!H48 | I32: ='02_P&L'!I48 | ... M32: ='02_P&L'!M48 | N32: ='02_P&L'!N51

Sheet 06_Growth_Drivers
A1: Growth Drivers | Consumption & Commercial Expansion
A2: 432 observations: month x region x channel x category | IDR juta where applicable
A5: Month | B5: Region | C5: Channel | D5: Category | E5: Consumption Volume | F5: Net Sales | G5: Numeric Distribution | H5: Weighted Distribution | I5: Digital Commerce Mix | J5: Media / Expert Investment | K5: Incremental Gross Profit | L5: Growth Rate | M5: Growth RAG
A6: Jan 2026 | B6: Jabodetabek | C6: General Trade | D6: Personal Care | E6: 410 | F6: 95 | G6: 0.52 | H6: 0.61 | I6: 0.06 | J6: 2 | K6: 21 | L6: 0 | M6: =IF(L6>=0,"Green",IF(ABS(L6)<='00_Readme'!$B$14,"Amber","Red"))
A7: Jan 2026 | B7: Jabodetabek | C7: General Trade | D7: Home Care | E7: 448 | F7: 111 | G7: 0.52 | H7: 0.62 | I7: 0.06 | J7: 3 | K7: 26 | L7: 0 | M7: =IF(L7>=0,"Green",IF(ABS(L7)<='00_Readme'!$B$14,"Amber","Red"))
A8: Jan 2026 | B8: Jabodetabek | C8: General Trade | D8: Beverages | E8: 486 | F8: 127 | G8: 0.52 | H8: 0.63 | I8: 0.06 | J8: 3 | K8: 32 | L8: 0 | M8: =IF(L8>=0,"Green",IF(ABS(L8)<='00_Readme'!$B$14,"Amber","Red"))
A9: Jan 2026 | B9: Jabodetabek | C9: Modern Trade | D9: Personal Care | E9: 485 | F9: 123 | G9: 0.56 | H9: 0.65 | I9: 0.14 | J9: 4 | K9: 27 | L9: 0 | M9: =IF(L9>=0,"Green",IF(ABS(L9)<='00_Readme'!$B$14,"Amber","Red"))
A10: Jan 2026 | B10: Jabodetabek | C10: Modern Trade | D10: Home Care | E10: 523 | F10: 139 | G10: 0.56 | H10: 0.66 | I10: 0.14 | J10: 5 | K10: 33 | L10: 0 | M10: =IF(L10>=0,"Green",IF(ABS(L10)<='00_Readme'!$B$14,"Amber","Red"))
A11: Jan 2026 | B11: Jabodetabek | C11: Modern Trade | D11: Beverages | E11: 561 | F11: 155 | G11: 0.56 | H11: 0.67 | I11: 0.14 | J11: 5 | K11: 39 | L11: 0 | M11: =IF(L11>=0,"Green",IF(ABS(L11)<='00_Readme'!$B$14,"Amber","Red"))
A12: Jan 2026 | B12: Jabodetabek | C12: E-commerce | D12: Personal Care | E12: 560 | F12: 151 | G12: 0.6 | H12: 0.69 | I12: 0.22 | J12: 6 | K12: 33 | L12: 0 | M12: =IF(L12>=0,"Green",IF(ABS(L12)<='00_Readme'!$B$14,"Amber","Red"))
A13: Jan 2026 | B13: Jabodetabek | C13: E-commerce | D13: Home Care | E13: 598 | F13: 167 | G13: 0.6 | H13: 0.7 | I13: 0.22 | J13: 7 | K13: 39 | L13: 0 | M13: =IF(L13>=0,"Green",IF(ABS(L13)<='00_Readme'!$B$14,"Amber","Red"))
A14: Jan 2026 | B14: Jabodetabek | C14: E-commerce | D14: Beverages | E14: 636 | F14: 183 | G14: 0.6 | H14: 0.71 | I14: 0.22 | J14: 8 | K14: 46 | L14: 0 | M14: =IF(L14>=0,"Green",IF(ABS(L14)<='00_Readme'!$B$14,"Amber","Red"))
A15: Jan 2026 | B15: Jawa Barat | C15: General Trade | D15: Personal Care | E15: 462 | F15: 108 | G15: 0.58 | H15: 0.67 | I15: 0.06 | J15: 3 | K15: 24 | L15: 0 | M15: =IF(L15>=0,"Green",IF(ABS(L15)<='00_Readme'!$B$14,"Amber","Red"))
A16: Jan 2026 | B16: Jawa Barat | C16: General Trade | D16: Home Care | E16: 500 | F16: 124 | G16: 0.58 | H16: 0.68 | I16: 0.06 | J16: 3 | K16: 29 | L16: 0 | M16: =IF(L16>=0,"Green",IF(ABS(L16)<='00_Readme'!$B$14,"Amber","Red"))
A17: Jan 2026 | B17: Jawa Barat | C17: General Trade | D17: Beverages | E17: 538 | F17: 140 | G17: 0.58 | H17: 0.69 | I17: 0.06 | J17: 4 | K17: 35 | L17: 0 | M17: =IF(L17>=0,"Green",IF(ABS(L17)<='00_Readme'!$B$14,"Amber","Red"))
... A41: Jan 2026 | B41: Jawa Timur | C41: E-commerce | D41: Beverages | E41: 792 | F41: 222 | G41: 0.78 | H41: 0.89 | I41: 0.22 | J41: 9 | K41: 56 | L41: 0 | M41: =IF(L41>=0,"Green",IF(ABS(L41)<='00_Readme'!$B$14,"Amber","Red"))
A42: Feb 2026 | B42: Jabodetabek | C42: General Trade | D42: Personal Care | E42: 448 | F42: 107 | G42: 0.53 | H42: 0.62 | I42: 0.07 | J42: 3 | K42: 24 | L42: =IFERROR(F42/F6-1,0) | M42: =IF(L42>=0,"Green",IF(ABS(L42)<='00_Readme'!$B$14,"Amber","Red"))
A43: Feb 2026 | B43: Jabodetabek | C43: General Trade | D43: Home Care | E43: 486 | F43: 123 | G43: 0.53 | H43: 0.63 | I43: 0.07 | J43: 3 | K43: 29 | L43: =IFERROR(F43/F7-1,0) | M43: =IF(L43>=0,"Green",IF(ABS(L43)<='00_Readme'!$B$14,"Amber","Red"))
A44: Feb 2026 | B44: Jabodetabek | C44: General Trade | D44: Beverages | E44: 524 | F44: 139 | G44: 0.53 | H44: 0.64 | I44: 0.07 | J44: 3 | K44: 35 | L44: =IFERROR(F44/F8-1,0) | M44: =IF(L44>=0,"Green",IF(ABS(L44)<='00_Readme'!$B$14,"Amber","Red"))
A45: Feb 2026 | B45: Jabodetabek | C45: Modern Trade | D45: Personal Care | E45: 523 | F45: 135 | G45: 0.57 | H45: 0.66 | I45: 0.15 | J45: 4 | K45: 30 | L45: =IFERROR(F45/F9-1,0) | M45: =IF(L45>=0,"Green",IF(ABS(L45)<='00_Readme'!$B$14,"Amber","Red"))
A46: Feb 2026 | B46: Jabodetabek | C46: Modern Trade | D46: Home Care | E46: 561 | F46: 151 | G46: 0.57 | H46: 0.67 | I46: 0.15 | J46: 5 | K46: 35 | L46: =IFERROR(F46/F10-1,0) | M46: =IF(L46>=0,"Green",IF(ABS(L46)<='00_Readme'!$B$14,"Amber","Red"))
A47: Feb 2026 | B47: Jabodetabek | C47: Modern Trade | D47: Beverages | E47: 599 | F47: 167 | G47: 0.57 | H47: 0.68 | I47: 0.15 | J47: 6 | K47: 42 | L47: =IFERROR(F47/F11-1,0) | M47: =IF(L47>=0,"Green",IF(ABS(L47)<='00_Readme'!$B$14,"Amber","Red"))
A48: Feb 2026 | B48: Jabodetabek | C48: E-commerce | D48: Personal Care | E48: 598 | F48: 163 | G48: 0.61 | H48: 0.7 | I48: 0.23 | J48: 7 | K48: 36 | L48: =IFERROR(F48/F12-1,0) | M48: =IF(L48>=0,"Green",IF(ABS(L48)<='00_Readme'!$B$14,"Amber","Red"))
A49: Feb 2026 | B49: Jabodetabek | C49: E-commerce | D49: Home Care | E49: 636 | F49: 179 | G49: 0.61 | H49: 0.71 | I49: 0.23 | J49: 7 | K49: 42 | L49: =IFERROR(F49/F13-1,0) | M49: =IF(L49>=0,"Green",IF(ABS(L49)<='00_Readme'!$B$14,"Amber","Red"))
A50: Feb 2026 | B50: Jabodetabek | C50: E-commerce | D50: Beverages | E50: 674 | F50: 195 | G50: 0.61 | H50: 0.72 | I50: 0.23 | J50: 8 | K50: 49 | L50: =IFERROR(F50/F14-1,0) | M50: =IF(L50>=0,"Green",IF(ABS(L50)<='00_Readme'!$B$14,"Amber","Red"))
A51: Feb 2026 | B51: Jawa Barat | C51: General Trade | D51: Personal Care | E51: 500 | F51: 120 | G51: 0.59 | H51: 0.68 | I51: 0.07 | J51: 3 | K51: 26 | L51: =IFERROR(F51/F15-1,0) | M51: =IF(L51>=0,"Green",IF(ABS(L51)<='00_Readme'!$B$14,"Amber","Red"))
A52: Feb 2026 | B52: Jawa Barat | C52: General Trade | D52: Home Care | E52: 538 | F52: 136 | G52: 0.59 | H52: 0.69 | I52: 0.07 | J52: 3 | K52: 32 | L52: =IFERROR(F52/F16-1,0) | M52: =IF(L52>=0,"Green",IF(ABS(L52)<='00_Readme'!$B$14,"Amber","Red"))
A53: Feb 2026 | B53: Jawa Barat | C53: General Trade | D53: Beverages | E53: 576 | F53: 152 | G53: 0.59 | H53: 0.7 | I53: 0.07 | J53: 4 | K53: 38 | L53: =IFERROR(F53/F17-1,0) | M53: =IF(L53>=0,"Green",IF(ABS(L53)<='00_Readme'!$B$14,"Amber","Red"))
... A437: Dec 2026 | B437: Jawa Timur | C437: E-commerce | D437: Beverages | E437: 1012 | F437: 298 | G437: 0.8 | H437: 0.91 | I437: 0.25 | J437: 12 | K437: 74 | L437: =IFERROR(F437/F401-1,0) | M437: =IF(L437>=0,"Green",IF(ABS(L437)<='00_Readme'!$B$14,"Amber","Red"))

Sheet 07_Strategic_Projects
A1: Strategic Projects | GTM, Innovation & Portfolio
A2: Project pipeline with formula ROI and RAG status | IDR juta
A5: Project ID | B5: Workstream | C5: Project | D5: Owner | E5: Sponsor | F5: Start | G5: End | H5: Budget | I5: Actual Spend | J5: Expected Revenue | K5: Expected Gross Profit | L5: ROI | M5: Milestone | N5: Status | O5: RAG
A6: PRJ-001 | B6: GTM | C6: Jabodetabek distributor re-segmentation | D6: Dina | E6: GM Commercial | F6: 46037 | G6: 46142 | H6: 850 | I6: 790 | J6: 4200 | K6: 1060 | L6: =IFERROR(K6/I6,0) | M6: Pilot completed | N6: Completed | O6: =IF(N6="Completed","Green",IF(N6="On Track","Green",IF(N6="At Risk","Amber","Red")))
A7: PRJ-002 | B7: Innovation | C7: Personal Care premium pack launch | D7: Rafi | E7: Marketing Director | F7: 46054 | G7: 46265 | H7: 1450 | I7: 990 | J7: 7200 | K7: 1720 | L7: =IFERROR(K7/I7,0) | M7: National launch readiness | N7: On Track | O7: =IF(N7="Completed","Green",IF(N7="On Track","Green",IF(N7="At Risk","Amber","Red")))
A8: PRJ-003 | B8: Digital Commerce | C8: Marketplace bundle engine | D8: Sari | E8: E-commerce Lead | F8: 46082 | G8: 46203 | H8: 720 | I8: 680 | J8: 3900 | K8: 780 | L8: =IFERROR(K8/I8,0) | M8: Partner API live | N8: On Track | O8: =IF(N8="Completed","Green",IF(N8="On Track","Green",IF(N8="At Risk","Amber","Red")))
A9: PRJ-004 | B9: Strategic Portfolio | C9: Home Care SKU rationalisation | D9: Bimo | E9: Supply Chain Director | F9: 46032 | G9: 46173 | H9: 560 | I9: 610 | J9: 1800 | K9: 410 | L9: =IFERROR(K9/I9,0) | M9: Decision gate 2 | N9: At Risk | O9: =IF(N9="Completed","Green",IF(N9="On Track","Green",IF(N9="At Risk","Amber","Red")))
A10: PRJ-005 | B10: GTM | C10: East Java route-to-market expansion | D10: Yuni | E10: GM Sales | F10: 46113 | G10: 46326 | H10: 1800 | I10: 940 | J10: 8600 | K10: 1880 | L10: =IFERROR(K10/I10,0) | M10: Distributor appointment | N10: On Track | O10: =IF(N10="Completed","Green",IF(N10="On Track","Green",IF(N10="At Risk","Amber","Red")))
A11: PRJ-006 | B11: Innovation | C11: Beverages zero-sugar renovation | D11: Arman | E11: R&D Director | F11: 46143 | G11: 46356 | H11: 2100 | I11: 1350 | J11: 9500 | K11: 2050 | L11: =IFERROR(K11/I11,0) | M11: Consumer test readout | N11: At Risk | O11: =IF(N11="Completed","Green",IF(N11="On Track","Green",IF(N11="At Risk","Amber","Red")))
A12: PRJ-007 | B12: Digital Commerce | C12: Live commerce expert program | D12: Maya | E12: Digital Director | F12: 46174 | G12: 46295 | H12: 480 | I12: 520 | J12: 2500 | K12: 510 | L12: =IFERROR(K12/I12,0) | M12: Host training | N12: Delayed | O12: =IF(N12="Completed","Green",IF(N12="On Track","Green",IF(N12="At Risk","Amber","Red")))
A13: PRJ-008 | B13: Strategic Portfolio | C13: Media mix effectiveness reset | D13: Fajar | E13: Finance Director | F13: 46204 | G13: 46371 | H13: 930 | I13: 420 | J13: 3300 | K13: 860 | L13: =IFERROR(K13/I13,0) | M13: Budget reallocation | N13: On Track | O13: =IF(N13="Completed","Green",IF(N13="On Track","Green",IF(N13="At Risk","Amber","Red")))

Sheet 08_Investment_Efficiency
A1: Investment Efficiency | Trade, A&P & Media ROI
A2: Detail by month x channel x category plus formula summary | IDR juta
A5: Month | B5: Channel | C5: Category | D5: Trade Investment | E5: A&P Investment | F5: Expert / Media Spend | G5: Gross Margin | H5: Overhead Target | I5: Actual Spend | J5: Incremental Sales | K5: Incremental Gross Profit | L5: ROI | M5: Variance vs Target | N5: RAG
A6: Jan 2026 | B6: General Trade | C6: Personal Care | D6: 80 | E6: 55 | F6: 30 | G6: ='02_P&L'!B9 | H6: ='02_P&L'!B24 | I6: 158 | J6: 310 | K6: 62 | L6: =IFERROR(K6/D6,0) | M6: =IFERROR(K6/J6-G6,0) | N6: =IF(M6>=0,"Green",IF(ABS(M6)<='00_Readme'!$B$14,"Amber","Red"))
A7: Jan 2026 | B7: General Trade | C7: Home Care | D7: 91 | E7: 63 | F7: 36 | G7: ='02_P&L'!B9 | H7: ='02_P&L'!B24 | I7: 187 | J7: 345 | K7: 76 | L7: =IFERROR(K7/D7,0) | M7: =IFERROR(K7/J7-G7,0) | N7: =IF(M7>=0,"Green",IF(ABS(M7)<='00_Readme'!$B$14,"Amber","Red"))
A8: Jan 2026 | B8: General Trade | C8: Beverages | D8: 102 | E8: 71 | F8: 42 | G8: ='02_P&L'!B9 | H8: ='02_P&L'!B24 | I8: 217 | J8: 380 | K8: 91 | L8: =IFERROR(K8/D8,0) | M8: =IFERROR(K8/J8-G8,0) | N8: =IF(M8>=0,"Green",IF(ABS(M8)<='00_Readme'!$B$14,"Amber","Red"))
A9: Jan 2026 | B9: Modern Trade | C9: Personal Care | D9: 102 | E9: 71 | F9: 43 | G9: ='02_P&L'!B9 | H9: ='02_P&L'!B24 | I9: 213 | J9: 380 | K9: 76 | L9: =IFERROR(K9/D9,0) | M9: =IFERROR(K9/J9-G9,0) | N9: =IF(M9>=0,"Green",IF(ABS(M9)<='00_Readme'!$B$14,"Amber","Red"))
A10: Jan 2026 | B10: Modern Trade | C10: Home Care | D10: 113 | E10: 79 | F10: 49 | G10: ='02_P&L'!B9 | H10: ='02_P&L'!B24 | I10: 243 | J10: 415 | K10: 91 | L10: =IFERROR(K10/D10,0) | M10: =IFERROR(K10/J10-G10,0) | N10: =IF(M10>=0,"Green",IF(ABS(M10)<='00_Readme'!$B$14,"Amber","Red"))
A11: Jan 2026 | B11: Modern Trade | C11: Beverages | D11: 124 | E11: 87 | F11: 55 | G11: ='02_P&L'!B9 | H11: ='02_P&L'!B24 | I11: 275 | J11: 450 | K11: 108 | L11: =IFERROR(K11/D11,0) | M11: =IFERROR(K11/J11-G11,0) | N11: =IF(M11>=0,"Green",IF(ABS(M11)<='00_Readme'!$B$14,"Amber","Red"))
A12: Jan 2026 | B12: E-commerce | C12: Personal Care | D12: 124 | E12: 87 | F12: 56 | G12: ='02_P&L'!B9 | H12: ='02_P&L'!B24 | I12: 270 | J12: 450 | K12: 90 | L12: =IFERROR(K12/D12,0) | M12: =IFERROR(K12/J12-G12,0) | N12: =IF(M12>=0,"Green",IF(ABS(M12)<='00_Readme'!$B$14,"Amber","Red"))
A13: Jan 2026 | B13: E-commerce | C13: Home Care | D13: 135 | E13: 95 | F13: 62 | G13: ='02_P&L'!B9 | H13: ='02_P&L'!B24 | I13: 302 | J13: 485 | K13: 107 | L13: =IFERROR(K13/D13,0) | M13: =IFERROR(K13/J13-G13,0) | N13: =IF(M13>=0,"Green",IF(ABS(M13)<='00_Readme'!$B$14,"Amber","Red"))
A14: Jan 2026 | B14: E-commerce | C14: Beverages | D14: 146 | E14: 103 | F14: 68 | G14: ='02_P&L'!B9 | H14: ='02_P&L'!B24 | I14: 304 | J14: 520 | K14: 125 | L14: =IFERROR(K14/D14,0) | M14: =IFERROR(K14/J14-G14,0) | N14: =IF(M14>=0,"Green",IF(ABS(M14)<='00_Readme'!$B$14,"Amber","Red"))
A15: Feb 2026 | B15: General Trade | C15: Personal Care | D15: 83 | E15: 57 | F15: 32 | G15: ='02_P&L'!C9 | H15: ='02_P&L'!C24 | I15: 169 | J15: 322 | K15: 64 | L15: =IFERROR(K15/D15,0) | M15: =IFERROR(K15/J15-G15,0) | N15: =IF(M15>=0,"Green",IF(ABS(M15)<='00_Readme'!$B$14,"Amber","Red"))
A16: Feb 2026 | B16: General Trade | C16: Home Care | D16: 94 | E16: 65 | F16: 38 | G16: ='02_P&L'!C9 | H16: ='02_P&L'!C24 | I16: 199 | J16: 357 | K16: 79 | L16: =IFERROR(K16/D16,0) | M16: =IFERROR(K16/J16-G16,0) | N16: =IF(M16>=0,"Green",IF(ABS(M16)<='00_Readme'!$B$14,"Amber","Red"))
A17: Feb 2026 | B17: General Trade | C17: Beverages | D17: 105 | E17: 73 | F17: 44 | G17: ='02_P&L'!C9 | H17: ='02_P&L'!C24 | I17: 230 | J17: 392 | K17: 94 | L17: =IFERROR(K17/D17,0) | M17: =IFERROR(K17/J17-G17,0) | N17: =IF(M17>=0,"Green",IF(ABS(M17)<='00_Readme'!$B$14,"Amber","Red"))
A18: Feb 2026 | B18: Modern Trade | C18: Personal Care | D18: 105 | E18: 73 | F18: 45 | G18: ='02_P&L'!C9 | H18: ='02_P&L'!C24 | I18: 225 | J18: 392 | K18: 78 | L18: =IFERROR(K18/D18,0) | M18: =IFERROR(K18/J18-G18,0) | N18: =IF(M18>=0,"Green",IF(ABS(M18)<='00_Readme'!$B$14,"Amber","Red"))
A19: Feb 2026 | B19: Modern Trade | C19: Home Care | D19: 116 | E19: 81 | F19: 51 | G19: ='02_P&L'!C9 | H19: ='02_P&L'!C24 | I19: 257 | J19: 427 | K19: 94 | L19: =IFERROR(K19/D19,0) | M19: =IFERROR(K19/J19-G19,0) | N19: =IF(M19>=0,"Green",IF(ABS(M19)<='00_Readme'!$B$14,"Amber","Red"))
A20: Feb 2026 | B20: Modern Trade | C20: Beverages | D20: 127 | E20: 89 | F20: 57 | G20: ='02_P&L'!C9 | H20: ='02_P&L'!C24 | I20: 262 | J20: 462 | K20: 111 | L20: =IFERROR(K20/D20,0) | M20: =IFERROR(K20/J20-G20,0) | N20: =IF(M20>=0,"Green",IF(ABS(M20)<='00_Readme'!$B$14,"Amber","Red"))
A21: Feb 2026 | B21: E-commerce | C21: Personal Care | D21: 127 | E21: 89 | F21: 58 | G21: ='02_P&L'!C9 | H21: ='02_P&L'!C24 | I21: 284 | J21: 462 | K21: 92 | L21: =IFERROR(K21/D21,0) | M21: =IFERROR(K21/J21-G21,0) | N21: =IF(M21>=0,"Green",IF(ABS(M21)<='00_Readme'!$B$14,"Amber","Red"))
A22: Feb 2026 | B22: E-commerce | C22: Home Care | D22: 138 | E22: 97 | F22: 64 | G22: ='02_P&L'!C9 | H22: ='02_P&L'!C24 | I22: 287 | J22: 497 | K22: 109 | L22: =IFERROR(K22/D22,0) | M22: =IFERROR(K22/J22-G22,0) | N22: =IF(M22>=0,"Green",IF(ABS(M22)<='00_Readme'!$B$14,"Amber","Red"))
A23: Feb 2026 | B23: E-commerce | C23: Beverages | D23: 149 | E23: 105 | F23: 70 | G23: ='02_P&L'!C9 | H23: ='02_P&L'!C24 | I23: 319 | J23: 532 | K23: 128 | L23: =IFERROR(K23/D23,0) | M23: =IFERROR(K23/J23-G23,0) | N23: =IF(M23>=0,"Green",IF(ABS(M23)<='00_Readme'!$B$14,"Amber","Red"))
A24: Mar 2026 | B24: General Trade | C24: Personal Care | D24: 86 | E24: 59 | F24: 34 | G24: ='02_P&L'!D9 | H24: ='02_P&L'!D24 | I24: 181 | J24: 334 | K24: 67 | L24: =IFERROR(K24/D24,0) | M24: =IFERROR(K24/J24-G24,0) | N24: =IF(M24>=0,"Green",IF(ABS(M24)<='00_Readme'!$B$14,"Amber","Red"))
A25: Mar 2026 | B25: General Trade | C25: Home Care | D25: 97 | E25: 67 | F25: 40 | G25: ='02_P&L'!D9 | H25: ='02_P&L'!D24 | I25: 211 | J25: 369 | K25: 81 | L25: =IFERROR(K25/D25,0) | M25: =IFERROR(K25/J25-G25,0) | N25: =IF(M25>=0,"Green",IF(ABS(M25)<='00_Readme'!$B$14,"Amber","Red"))
A26: Mar 2026 | B26: General Trade | C26: Beverages | D26: 108 | E26: 75 | F26: 46 | G26: ='02_P&L'!D9 | H26: ='02_P&L'!D24 | I26: 220 | J26: 404 | K26: 97 | L26: =IFERROR(K26/D26,0) | M26: =IFERROR(K26/J26-G26,0) | N26: =IF(M26>=0,"Green",IF(ABS(M26)<='00_Readme'!$B$14,"Amber","Red"))
A27: Mar 2026 | B27: Modern Trade | C27: Personal Care | D27: 108 | E27: 75 | F27: 47 | G27: ='02_P&L'!D9 | H27: ='02_P&L'!D24 | I27: 238 | J27: 404 | K27: 81 | L27: =IFERROR(K27/D27,0) | M27: =IFERROR(K27/J27-G27,0) | N27: =IF(M27>=0,"Green",IF(ABS(M27)<='00_Readme'!$B$14,"Amber","Red"))
A28: Mar 2026 | B28: Modern Trade | C28: Home Care | D28: 119 | E28: 83 | F28: 53 | G28: ='02_P&L'!D9 | H28: ='02_P&L'!D24 | I28: 245 | J28: 439 | K28: 97 | L28: =IFERROR(K28/D28,0) | M28: =IFERROR(K28/J28-G28,0) | N28: =IF(M28>=0,"Green",IF(ABS(M28)<='00_Readme'!$B$14,"Amber","Red"))
A29: Mar 2026 | B29: Modern Trade | C29: Beverages | D29: 130 | E29: 91 | F29: 59 | G29: ='02_P&L'!D9 | H29: ='02_P&L'!D24 | I29: 276 | J29: 474 | K29: 114 | L29: =IFERROR(K29/D29,0) | M29: =IFERROR(K29/J29-G29,0) | N29: =IF(M29>=0,"Green",IF(ABS(M29)<='00_Readme'!$B$14,"Amber","Red"))
A30: Mar 2026 | B30: E-commerce | C30: Personal Care | D30: 130 | E30: 91 | F30: 60 | G30: ='02_P&L'!D9 | H30: ='02_P&L'!D24 | I30: 270 | J30: 474 | K30: 95 | L30: =IFERROR(K30/D30,0) | M30: =IFERROR(K30/J30-G30,0) | N30: =IF(M30>=0,"Green",IF(ABS(M30)<='00_Readme'!$B$14,"Amber","Red"))
A31: Mar 2026 | B31: E-commerce | C31: Home Care | D31: 141 | E31: 99 | F31: 66 | G31: ='02_P&L'!D9 | H31: ='02_P&L'!D24 | I31: 301 | J31: 509 | K31: 112 | L31: =IFERROR(K31/D31,0) | M31: =IFERROR(K31/J31-G31,0) | N31: =IF(M31>=0,"Green",IF(ABS(M31)<='00_Readme'!$B$14,"Amber","Red"))
A32: Mar 2026 | B32: E-commerce | C32: Beverages | D32: 152 | E32: 107 | F32: 72 | G32: ='02_P&L'!D9 | H32: ='02_P&L'!D24 | I32: 334 | J32: 544 | K32: 131 | L32: =IFERROR(K32/D32,0) | M32: =IFERROR(K32/J32-G32,0) | N32: =IF(M32>=0,"Green",IF(ABS(M32)<='00_Readme'!$B$14,"Amber","Red"))
A33: Apr 2026 | B33: General Trade | C33: Personal Care | D33: 89 | E33: 61 | F33: 36 | G33: ='02_P&L'!E9 | H33: ='02_P&L'!E24 | I33: 193 | J33: 346 | K33: 69 | L33: =IFERROR(K33/D33,0) | M33: =IFERROR(K33/J33-G33,0) | N33: =IF(M33>=0,"Green",IF(ABS(M33)<='00_Readme'!$B$14,"Amber","Red"))
A34: Apr 2026 | B34: General Trade | C34: Home Care | D34: 100 | E34: 69 | F34: 42 | G34: ='02_P&L'!E9 | H34: ='02_P&L'!E24 | I34: 203 | J34: 381 | K34: 84 | L34: =IFERROR(K34/D34,0) | M34: =IFERROR(K34/J34-G34,0) | N34: =IF(M34>=0,"Green",IF(ABS(M34)<='00_Readme'!$B$14,"Amber","Red"))
A35: Apr 2026 | B35: General Trade | C35: Beverages | D35: 111 | E35: 77 | F35: 48 | G35: ='02_P&L'!E9 | H35: ='02_P&L'!E24 | I35: 232 | J35: 416 | K35: 100 | L35: =IFERROR(K35/D35,0) | M35: =IFERROR(K35/J35-G35,0) | N35: =IF(M35>=0,"Green",IF(ABS(M35)<='00_Readme'!$B$14,"Amber","Red"))
A36: Apr 2026 | B36: Modern Trade | C36: Personal Care | D36: 111 | E36: 77 | F36: 49 | G36: ='02_P&L'!E9 | H36: ='02_P&L'!E24 | I36: 228 | J36: 416 | K36: 83 | L36: =IFERROR(K36/D36,0) | M36: =IFERROR(K36/J36-G36,0) | N36: =IF(M36>=0,"Green",IF(ABS(M36)<='00_Readme'!$B$14,"Amber","Red"))
A37: Apr 2026 | B37: Modern Trade | C37: Home Care | D37: 122 | E37: 85 | F37: 55 | G37: ='02_P&L'!E9 | H37: ='02_P&L'!E24 | I37: 258 | J37: 451 | K37: 99 | L37: =IFERROR(K37/D37,0) | M37: =IFERROR(K37/J37-G37,0) | N37: =IF(M37>=0,"Green",IF(ABS(M37)<='00_Readme'!$B$14,"Amber","Red"))
A38: Apr 2026 | B38: Modern Trade | C38: Beverages | D38: 133 | E38: 93 | F38: 61 | G38: ='02_P&L'!E9 | H38: ='02_P&L'!E24 | I38: 290 | J38: 486 | K38: 117 | L38: =IFERROR(K38/D38,0) | M38: =IFERROR(K38/J38-G38,0) | N38: =IF(M38>=0,"Green",IF(ABS(M38)<='00_Readme'!$B$14,"Amber","Red"))
A39: Apr 2026 | B39: E-commerce | C39: Personal Care | D39: 133 | E39: 93 | F39: 62 | G39: ='02_P&L'!E9 | H39: ='02_P&L'!E24 | I39: 284 | J39: 486 | K39: 97 | L39: =IFERROR(K39/D39,0) | M39: =IFERROR(K39/J39-G39,0) | N39: =IF(M39>=0,"Green",IF(ABS(M39)<='00_Readme'!$B$14,"Amber","Red"))
A40: Apr 2026 | B40: E-commerce | C40: Home Care | D40: 144 | E40: 101 | F40: 68 | G40: ='02_P&L'!E9 | H40: ='02_P&L'!E24 | I40: 316 | J40: 521 | K40: 115 | L40: =IFERROR(K40/D40,0) | M40: =IFERROR(K40/J40-G40,0) | N40: =IF(M40>=0,"Green",IF(ABS(M40)<='00_Readme'!$B$14,"Amber","Red"))
A41: Apr 2026 | B41: E-commerce | C41: Beverages | D41: 155 | E41: 109 | F41: 74 | G41: ='02_P&L'!E9 | H41: ='02_P&L'!E24 | I41: 350 | J41: 556 | K41: 133 | L41: =IFERROR(K41/D41,0) | M41: =IFERROR(K41/J41-G41,0) | N41: =IF(M41>=0,"Green",IF(ABS(M41)<='00_Readme'!$B$14,"Amber","Red"))
A42: May 2026 | B42: General Trade | C42: Personal Care | D42: 92 | E42: 63 | F42: 38 | G42: ='02_P&L'!F9 | H42: ='02_P&L'!F24 | I42: 185 | J42: 358 | K42: 72 | L42: =IFERROR(K42/D42,0) | M42: =IFERROR(K42/J42-G42,0) | N42: =IF(M42>=0,"Green",IF(ABS(M42)<='00_Readme'!$B$14,"Amber","Red"))
...

Sheet 09_Business_Partnering
A1: Business Partnering | Performance, Hygiene & Market Risk
A2: KPI scorecard and risk register | management indicators are dummy values
A4: Business Partnering KPI Scorecard
A5: KPI | B5: Target | C5: Actual | D5: Variance | E5: RAG | F5: Root Cause | G5: Action Plan | H5: Owner | I5: Due Date
A6: Performance culture | B6: 0.9 | C6: 0.88 | D6: =C6-B6 | E6: =IF(C6>=B6,"Green",IF(B6-C6<=B6*'00_Readme'!$B$14,"Amber","Red")) | F6: Manager routines inconsistent in two regions | G6: Weekly performance huddle and scorecard coaching | H6: Dina | I6: 46112
A7: Commercial hygiene | B7: 0.95 | C7: 0.91 | D7: =C7-B7 | E7: =IF(C7>=B7,"Green",IF(B7-C7<=B7*'00_Readme'!$B$14,"Amber","Red")) | F7: Late promo accrual documentation | G7: Close checklist and exception review | H7: Bimo | I7: 46081
A8: Market Risk Assessment | B8: 1 | C8: 0.92 | D8: =C8-B8 | E8: =IF(C8>=B8,"Green",IF(B8-C8<=B8*'00_Readme'!$B$14,"Amber","Red")) | F8: Two key distributors lack refreshed risk rating | G8: Complete quarterly distributor risk review | H8: Fajar | I8: 46127
A9: Forecast Accuracy | B9: 0.95 | C9: ='01_Dashboard'!J9 | D9: =C9-B9 | E9: =IF(C9>=B9,"Green",IF(B9-C9<=B9*'00_Readme'!$B$14,"Amber","Red")) | F9: Promo phasing creates volume timing gaps | G9: Use rolling demand signal and bias review | H9: Sari | I9: 46157
A10: Distribution Reach | B10: 0.85 | C10: 0.83 | D10: =C10-B10 | E10: =IF(C10>=B10,"Green",IF(B10-C10<=B10*'00_Readme'!$B$14,"Amber","Red")) | F10: Numeric distribution soft in East Java | G10: Route-to-market expansion pilot | H10: Yuni | I10: 46203
A11: Inventory Health | B11: 0.9 | C11: 0.86 | D11: =C11-B11 | E11: =IF(C11>=B11,"Green",IF(B11-C11<=B11*'00_Readme'!$B$14,"Amber","Red")) | F11: Beverages inventory above target | G11: SKU rationalisation and replenishment guardrails | H11: Arman | I11: 46142
A18: Market Risk Register
A19: Risk ID | B19: Risk | C19: Category | D19: Probability | E19: Impact | F19: Exposure | G19: Mitigation | H19: Owner | I19: Due Date | J19: Status | K19: RAG
A20: R-001 | B20: Distributor credit deterioration | C20: Credit | D20: 0.45 | E20: 5 | F20: =D20*E20 | G20: Fajar | H20: 46068 | I20: Open | K20: =IF(J20="Mitigated","Green",IF(F20>=2,"Red",IF(F20>=1,"Amber","Green")))
A21: R-002 | B21: Raw material cost inflation | C21: Supply | D21: 0.55 | E21: 4 | F21: =D21*E21 | G21: Arman | H21: 46112 | I21: Open | K21: =IF(J21="Mitigated","Green",IF(F21>=2,"Red",IF(F21>=1,"Amber","Green")))
A22: R-003 | B22: Promo leakage / claim quality | C22: Commercial | D22: 0.35 | E22: 4 | F22: =D22*E22 | G22: Bimo | H22: 46081 | I22: Monitoring | K22: =IF(J22="Mitigated","Green",IF(F22>=2,"Red",IF(F22>=1,"Amber","Green")))
A23: R-004 | B23: E-commerce platform dependency | C23: Digital | D23: 0.5 | E23: 3 | F23: =D23*E23 | G23: Sari | H23: 46172 | I23: Open | K23: =IF(J23="Mitigated","Green",IF(F23>=2,"Red",IF(F23>=1,"Amber","Green")))
A24: R-005 | B24: Tax audit documentation gap | C24: Compliance | D24: 0.25 | E24: 5 | F24: =D24*E24 | G24: Dina | H24: 46053 | I24: Mitigated | K24: =IF(J24="Mitigated","Green",IF(F24>=2,"Red",IF(F24>=1,"Amber","Green")))
A25: R-006 | B25: Service level underperformance | C25: Operations | D25: 0.4 | E25: 3 | F25: =D25*E25 | G25: Yuni | H25: 46142 | I25: Open | K25: =IF(J25="Mitigated","Green",IF(F25>=2,"Red",IF(F25>=1,"Amber","Green")))
A26: R-007 | B26: FX exposure on imported inputs | C26: Treasury | D26: 0.3 | E26: 4 | F26: =D26*E26 | G26: Fajar | H26: 46203 | I26: Monitoring | K26: =IF(J26="Mitigated","Green",IF(F26>=2,"Red",IF(F26>=1,"Amber","Green")))
A27: R-008 | B27: Data quality in management book | C27: Control | D27: 0.2 | E27: 4 | F27: =D27*E27 | G27: Dina | H27: 46042 | I27: Mitigated | K27: =IF(J27="Mitigated","Green",IF(F27>=2,"Red",IF(F27>=1,"Amber","Green")))

Sheet 10_Audit_Compliance
A1: Audit & Compliance
A2: Dummy governance tracker for statutory, external financial, tax, management book and accounting controls
A4: Audit and Control Plan
A5: Control Area | B5: Audit Type | C5: Management Book | D5: Due Date | E5: Owner | F5: Issue Count | G5: Remediation | H5: Status | I5: RAG
A6: Year-end statutory accounts | B6: Statutory audit | C6: Complete | D6: 46433 | E6: Dina | F6: 2 | G6: 0.75 | H6: In Progress | I6: =IF(H6="Complete","Green",IF(OR(F6>2,G6<0.7),"Red","Amber"))
A7: External financial statements | B7: External financial audit | C7: Complete | D7: 46461 | E7: Fajar | F7: 1 | G7: 0.9 | H7: In Progress | I7: =IF(H7="Complete","Green",IF(OR(F7>2,G7<0.7),"Red","Amber"))
A8: VAT and withholding tax | B8: Tax audit | C8: Complete | D8: 46265 | E8: Bimo | F8: 3 | G8: 0.6 | H8: Open | I8: =IF(H8="Complete","Green",IF(OR(F8>2,G8<0.7),"Red","Amber"))
A9: Monthly close pack | B9: Management book | C9: Complete | D9: 46032 | E9: Dina | F9: 0 | G9: 1 | H9: Complete | I9: =IF(H9="Complete","Green",IF(OR(F9>2,G9<0.7),"Red","Amber"))
A10: Revenue recognition control | B10: Accounting control | C10: In Review | D10: 46142 | E10: Sari | F10: 1 | G10: 0.8 | H10: In Progress | I10: =IF(H10="Complete","Green",IF(OR(F10>2,G10<0.7),"Red","Amber"))
A11: Trade spend accrual control | B11: Accounting control | C11: In Review | D11: 46173 | E11: Bimo | F11: 2 | G11: 0.55 | H11: Open | I11: =IF(H11="Complete","Green",IF(OR(F11>2,G11<0.7),"Red","Amber"))
A12: Inventory provision review | B12: Accounting control | C12: Complete | D12: 46203 | E12: Arman | F12: 1 | G12: 0.85 | H12: In Progress | I12: =IF(H12="Complete","Green",IF(OR(F12>2,G12<0.7),"Red","Amber"))
A13: Fixed asset verification | B13: Accounting control | C13: Complete | D13: 46295 | E13: Yuni | F13: 0 | G13: 1 | H13: Complete | I13: =IF(H13="Complete","Green",IF(OR(F13>2,G13<0.7),"Red","Amber"))
